Workbook

Sheet Synthèse
A1: VITRACO Moto — Plan de test du jalon V1
A2: Lot 1 « Stock et logistique » · document de recette · version du 18 octobre 2026
A4: 1. Objet et conditions de passage
A5: Le jalon V1 correspond au Lot 1 « Stock et logistique » du plan de livraison (SRS 13.4). Condition de mise en service : « Stock initial importé par châssis et rapproché par scan au magasin et dans les boutiques ». Ce classeur contient les cas de test à jouer à la main, les scénarios de recette de bout en bout, la checklist de reprise des données, la traçabilité vers les user stories, et le suivi des anomalies.
A6: Périmètre : sprints S1 (socle et catalogue), S2 (importation et réception par scan) et S3 (stock, transferts) : US-001 à 008, 010 à 013, 020 à 027, 040 à 046 et 155, avec les modules ADM, CAT, APP, REC, STK, TRF, l'import du stock initial et le rapprochement par pointage.
A7: Les scénarios R1 (partie réception), R6 et R10 (partie droits) du SRS 14.1 sont repris dans l'onglet « Recette Lot 1 ». Les scénarios R2 à R5, R7 à R9, R11 et R12 relèvent des lots 2 à 4.
A9: 2. Avancement (calculé à partir de l'onglet « Plan de test »)
A10: Cas de test au plan | B10: =COUNTA('Plan de test'!$A$5:$A$152)
A11: Cas à jouer (livrés ou partiels) | B11: =COUNTA('Plan de test'!$A$5:$A$152)-COUNTIF('Plan de test'!$M$5:$M$152,"Non livré")-COUNTIF('Plan de test'!$M$5:$M$152,"Non applicable")
A12: Réussis | B12: =COUNTIF('Plan de test'!$M$5:$M$152,"Réussi")
A13: En échec | B13: =COUNTIF('Plan de test'!$M$5:$M$152,"Échec")
A14: Bloqués | B14: =COUNTIF('Plan de test'!$M$5:$M$152,"Bloqué")
A15: Restant à tester | B15: =COUNTIF('Plan de test'!$M$5:$M$152,"À tester")
A16: Non livrés (à rejouer plus tard) | B16: =COUNTIF('Plan de test'!$M$5:$M$152,"Non livré")
A17: Taux d'exécution | B17: =IF(B11=0,0,(B12+B13+B14)/B11)
A18: Taux de réussite (sur cas exécutés) | B18: =IF((B12+B13+B14)=0,0,B12/(B12+B13+B14))
A20: 3. Avancement par module
A21: Module | B21: Cas | C21: À tester | D21: Réussis | E21: Échecs | F21: Bloqués | G21: Non livrés | H21: % réussi
A22: ADM Administration | B22: =COUNTIF('Plan de test'!$B$5:$B$152,A22) | C22: =COUNTIFS('Plan de test'!$B$5:$B$152,A22,'Plan de test'!$M$5:$M$152,"À tester") | D22: =COUNTIFS('Plan de test'!$B$5:$B$152,A22,'Plan de test'!$M$5:$M$152,"Réussi") | E22: =COUNTIFS('Plan de test'!$B$5:$B$152,A22,'Plan de test'!$M$5:$M$152,"Échec") | F22: =COUNTIFS('Plan de test'!$B$5:$B$152,A22,'Plan de test'!$M$5:$M$152,"Bloqué") | G22: =COUNTIFS('Plan de test'!$B$5:$B$152,A22,'Plan de test'!$M$5:$M$152,"Non livré") | H22: =IF(B22-G22=0,0,D22/(B22-G22))
A23: CAT Catalogue et châssis | B23: =COUNTIF('Plan de test'!$B$5:$B$152,A23) | C23: =COUNTIFS('Plan de test'!$B$5:$B$152,A23,'Plan de test'!$M$5:$M$152,"À tester") | D23: =COUNTIFS('Plan de test'!$B$5:$B$152,A23,'Plan de test'!$M$5:$M$152,"Réussi") | E23: =COUNTIFS('Plan de test'!$B$5:$B$152,A23,'Plan de test'!$M$5:$M$152,"Échec") | F23: =COUNTIFS('Plan de test'!$B$5:$B$152,A23,'Plan de test'!$M$5:$M$152,"Bloqué") | G23: =COUNTIFS('Plan de test'!$B$5:$B$152,A23,'Plan de test'!$M$5:$M$152,"Non livré") | H23: =IF(B23-G23=0,0,D23/(B23-G23))
A24: APP Approvisionnements | B24: =COUNTIF('Plan de test'!$B$5:$B$152,A24) | C24: =COUNTIFS('Plan de test'!$B$5:$B$152,A24,'Plan de test'!$M$5:$M$152,"À tester") | D24: =COUNTIFS('Plan de test'!$B$5:$B$152,A24,'Plan de test'!$M$5:$M$152,"Réussi") | E24: =COUNTIFS('Plan de test'!$B$5:$B$152,A24,'Plan de test'!$M$5:$M$152,"Échec") | F24: =COUNTIFS('Plan de test'!$B$5:$B$152,A24,'Plan de test'!$M$5:$M$152,"Bloqué") | G24: =COUNTIFS('Plan de test'!$B$5:$B$152,A24,'Plan de test'!$M$5:$M$152,"Non livré") | H24: =IF(B24-G24=0,0,D24/(B24-G24))
A25: REC Réceptions | B25: =COUNTIF('Plan de test'!$B$5:$B$152,A25) | C25: =COUNTIFS('Plan de test'!$B$5:$B$152,A25,'Plan de test'!$M$5:$M$152,"À tester") | D25: =COUNTIFS('Plan de test'!$B$5:$B$152,A25,'Plan de test'!$M$5:$M$152,"Réussi") | E25: =COUNTIFS('Plan de test'!$B$5:$B$152,A25,'Plan de test'!$M$5:$M$152,"Échec") | F25: =COUNTIFS('Plan de test'!$B$5:$B$152,A25,'Plan de test'!$M$5:$M$152,"Bloqué") | G25: =COUNTIFS('Plan de test'!$B$5:$B$152,A25,'Plan de test'!$M$5:$M$152,"Non livré") | H25: =IF(B25-G25=0,0,D25/(B25-G25))
A26: STK Stock | B26: =COUNTIF('Plan de test'!$B$5:$B$152,A26) | C26: =COUNTIFS('Plan de test'!$B$5:$B$152,A26,'Plan de test'!$M$5:$M$152,"À tester") | D26: =COUNTIFS('Plan de test'!$B$5:$B$152,A26,'Plan de test'!$M$5:$M$152,"Réussi") | E26: =COUNTIFS('Plan de test'!$B$5:$B$152,A26,'Plan de test'!$M$5:$M$152,"Échec") | F26: =COUNTIFS('Plan de test'!$B$5:$B$152,A26,'Plan de test'!$M$5:$M$152,"Bloqué") | G26: =COUNTIFS('Plan de test'!$B$5:$B$152,A26,'Plan de test'!$M$5:$M$152,"Non livré") | H26: =IF(B26-G26=0,0,D26/(B26-G26))
A27: TRF Transferts | B27: =COUNTIF('Plan de test'!$B$5:$B$152,A27) | C27: =COUNTIFS('Plan de test'!$B$5:$B$152,A27,'Plan de test'!$M$5:$M$152,"À tester") | D27: =COUNTIFS('Plan de test'!$B$5:$B$152,A27,'Plan de test'!$M$5:$M$152,"Réussi") | E27: =COUNTIFS('Plan de test'!$B$5:$B$152,A27,'Plan de test'!$M$5:$M$152,"Échec") | F27: =COUNTIFS('Plan de test'!$B$5:$B$152,A27,'Plan de test'!$M$5:$M$152,"Bloqué") | G27: =COUNTIFS('Plan de test'!$B$5:$B$152,A27,'Plan de test'!$M$5:$M$152,"Non livré") | H27: =IF(B27-G27=0,0,D27/(B27-G27))
A28: REP Reprise du stock | B28: =COUNTIF('Plan de test'!$B$5:$B$152,A28) | C28: =COUNTIFS('Plan de test'!$B$5:$B$152,A28,'Plan de test'!$M$5:$M$152,"À tester") | D28: =COUNTIFS('Plan de test'!$B$5:$B$152,A28,'Plan de test'!$M$5:$M$152,"Réussi") | E28: =COUNTIFS('Plan de test'!$B$5:$B$152,A28,'Plan de test'!$M$5:$M$152,"Échec") | F28: =COUNTIFS('Plan de test'!$B$5:$B$152,A28,'Plan de test'!$M$5:$M$152,"Bloqué") | G28: =COUNTIFS('Plan de test'!$B$5:$B$152,A28,'Plan de test'!$M$5:$M$152,"Non livré") | H28: =IF(B28-G28=0,0,D28/(B28-G28))
A29: TRV Transverse | B29: =COUNTIF('Plan de test'!$B$5:$B$152,A29) | C29: =COUNTIFS('Plan de test'!$B$5:$B$152,A29,'Plan de test'!$M$5:$M$152,"À tester") | D29: =COUNTIFS('Plan de test'!$B$5:$B$152,A29,'Plan de test'!$M$5:$M$152,"Réussi") | E29: =COUNTIFS('Plan de test'!$B$5:$B$152,A29,'Plan de test'!$M$5:$M$152,"Échec") | F29: =COUNTIFS('Plan de test'!$B$5:$B$152,A29,'Plan de test'!$M$5:$M$152,"Bloqué") | G29: =COUNTIFS('Plan de test'!$B$5:$B$152,A29,'Plan de test'!$M$5:$M$152,"Non livré") | H29: =IF(B29-G29=0,0,D29/(B29-G29))
A30: Total | B30: =SUM(B22:B29) | C30: =SUM(C22:C29) | D30: =SUM(D22:D29) | E30: =SUM(E22:E29) | F30: =SUM(F22:F29) | G30: =SUM(G22:G29) | H30: =IF(B30-G30=0,0,D30/(B30-G30))
A32: 4. Critères de sortie du jalon (go / no-go)
A33: Critère | B33: État | C33: Précision
A34: Tous les cas « Doit » livrés sont réussis | B34: =IF(COUNTIFS('Plan de test'!$J$5:$J$152,"M",'Plan de test'!$K$5:$K$152,"<>À livrer",'Plan de test'!$M$5:$M$152,"<>Réussi")=0,"OK","À faire") | C34: Les cas partiels sont jugés sur ce qui est livré ; l'écart est consigné dans les limites connues.
A35: Aucun cas en échec ni bloqué | B35: =IF(COUNTIF('Plan de test'!$M$5:$M$152,"Échec")+COUNTIF('Plan de test'!$M$5:$M$152,"Bloqué")=0,"OK","À faire") | C35: Chaque échec ouvre une anomalie dans l'onglet « Anomalies ».
A36: Aucune anomalie bloquante ou majeure ouverte | B36: =IF(COUNTIFS(Anomalies!$D$5:$D$300,"Bloquante",Anomalies!$G$5:$G$300,"<>Fermée")+COUNTIFS(Anomalies!$D$5:$D$300,"Majeure",Anomalies!$G$5:$G$300,"<>Fermée")=0,"OK","À faire") | C36: Seules des anomalies mineures peuvent rester ouvertes, avec un plan de correction.
A37: Stock d'ouverture rapproché à écart nul sur chaque site | B37: =IF(AND('Reprise des données'!H17="Oui",'Reprise des données'!H18="Oui",'Reprise des données'!H19="Oui"),"OK","À faire") | C37: Magasin, boutique pilote, seconde boutique : voir le tableau de rapprochement de l'onglet « Reprise des données ».
A38: Scénarios RV1-01 à RV1-07 joués sans écart | B38: =IF(AND(COUNTIF('Recette Lot 1'!$G$5:$G$200,"Échec")=0,COUNTIF('Recette Lot 1'!$G$5:$G$200,"Bloqué")=0,COUNTIF('Recette Lot 1'!$G$5:$G$200,"À faire")=0),"OK","À faire") | C38: Chaque étape de chaque scénario doit être renseignée « Réussi ».
A39: Données de reprise validées par leurs responsables | B39: =IF(COUNTIF('Reprise des données'!$G$5:$G$10,"Validé")=ROWS('Reprise des données'!$G$5:$G$10),"OK","À faire") | C39: Onglet « Reprise des données », colonne Statut.
A40: Tests automatiques au vert | B40: À faire | C40: À confirmer avant la recette : exécuter la suite complète (mvn test) sur la version déployée.
A42: 5. Limites connues du lot (cas « Partiel » ou « À livrer »)
A43: Fonction | B43: Réf. SRS | C43: Situation dans ce lot
A44: Photo des motos endommagées et pièces jointes | B44: US-027, US-042, EF-TRF-06 | C44: Le module Documents (pièces, photos, archivage du bon signé) arrive au sprint S10. Dans ce lot : motif texte et référence de pièce.
A45: Scan par appareil photo (caméra) | B45: US-024, EF-REC-10 | C45: Saisie au clavier et lecteur de codes-barres externe livrés ; la lecture par caméra est à ajouter.
...

Sheet Plan de test
A1: Plan de test — Jalon V1 · Lot 1 « Stock et logistique »
A2: Un cas par ligne. Remplir les colonnes Résultat, Date, Testeur, N° anomalie et Commentaire. Les listes déroulantes sont dans les colonnes Résultat et Prio.
A3: Légende : Prio. M = Doit, S = Devrait, C = Pourrait (SRS 1.3). Couverture développement : Livré / Partiel (voir commentaire et onglet Synthèse) / À livrer (cas à rejouer plus tard).
A4: N° | B4: Module | C4: Référence (story / exigence) | D4: Cas de test | E4: Profil testeur | F4: Pré-requis | G4: Étapes | H4: Résultat attendu | I4: Type | J4: Prio. | K4: Couverture développement | L4: Test automatique | M4: Résultat | N4: Date | O4: Testeur | P4: N° anomalie | Q4: Commentaire / preuve
A5: TC-ADM-001 | B5: ADM Administration | C5: US-001, EF-ADM-02 | D5: Créer un utilisateur avec ses rôles et ses emplacements | E5: Administrateur | F5: Un magasin et une boutique existent. Un rôle « magasin » existe. | G5: 1. Utilisateurs > Nouvel utilisateur. 2. Saisir nom, prénom, e-mail, rôle « Magasin », emplacement « Magasin de Cotonou ». 3. Enregistrer. 4. Ouvrir le lien d'activation reçu, choisir un mot de passe conforme. 5. Se connecter avec le nouveau compte. | H5: Le compte est créé « En attente d'activation » et passe « Actif » après activation. L'utilisateur voit ses rôles et son seul emplacement sur l'accueil. La création figure au journal d'audit (auteur, date, valeurs). | I5: Fonctionnel | J5: M | K5: Livré | L5: AuthEtUtilisateursTest | M5: À tester
A6: TC-ADM-002 | B6: ADM Administration | C6: US-001, EF-ADM-13 | D6: Périmètre : un utilisateur ne voit que ses emplacements | E6: Magasinier (Cotonou) | F6: Un second magasin et un châssis disponible dans chacun. | G6: 1. Se connecter en magasinier de Cotonou. 2. Stock > Stock : consulter la synthèse. 3. Tenter d'ouvrir par l'adresse la fiche d'un châssis de l'autre magasin. 4. Idem pour une réception et un transfert de l'autre magasin. | H6: Seul le stock de Cotonou apparaît. La fiche, la réception et le transfert de l'autre magasin répondent « introuvable » (404), sans révéler leur existence. | I6: Droits et périmètre | J6: M | K6: Livré | L6: StockTest, ChassisTest, ReceptionsTest, TransfertsTest | M6: À tester
A7: TC-ADM-003 | B7: ADM Administration | C7: US-001 | D7: Lien d'activation expiré ou déjà utilisé | E7: Administrateur | F7: Un utilisateur en attente d'activation. | G7: 1. Utiliser le lien d'activation une première fois. 2. Réutiliser le même lien. 3. Pour un lien expiré : Utilisateurs > Renvoyer l'activation, puis utiliser l'ancien lien. | H7: Le second usage est refusé avec un message clair. L'ancien lien est invalidé par le nouveau. Le renvoi est tracé au journal. | I7: Fonctionnel | J7: M | K7: Livré | L7: AuthEtUtilisateursTest | M7: À tester
A8: TC-ADM-004 | B8: ADM Administration | C8: US-002, EF-ADM-10 | D8: Verrouillage du compte après cinq échecs de connexion | E8: Tout profil | F8: Un compte actif de test (sans second facteur). | G8: 1. Saisir 5 fois un mauvais mot de passe. 2. Saisir ensuite le bon mot de passe. 3. En administrateur, constater l'état du compte puis le déverrouiller. | H8: Après le 5e échec le compte est verrouillé (message identique à un échec simple, sans indice). Le bon mot de passe est refusé tant que le compte est verrouillé. Les échecs et le verrouillage figurent au journal de sécurité. | I8: Fonctionnel | J8: M | K8: Livré | L8: AuthEtUtilisateursTest | M8: À tester
A9: TC-ADM-005 | B9: ADM Administration | C9: US-002, EF-ADM-10 | D9: Second facteur obligatoire pour Administrateur, Direction et Comptabilité | E9: Direction | F9: Un compte Direction sans second facteur activé ; une application d'authentification sur téléphone. | G9: 1. Se connecter avec e-mail et mot de passe. 2. Scanner le QR code (ou saisir la clé) puis saisir le code à 6 chiffres. 3. Noter les codes de secours affichés. 4. Se déconnecter puis se reconnecter : saisir le code TOTP. 5. Tenter un code erroné, puis un code de secours (une seule fois). | H9: Sans enrôlement, l'accès est impossible. Le code correct ouvre la session, le code erroné est refusé, un code de secours ne marche qu'une fois. Les secrets sont stockés chiffrés. | I9: Fonctionnel | J9: M | K9: Livré | L9: DoubleAuthentificationTest, TotpTest | M9: À tester
A10: TC-ADM-006 | B10: ADM Administration | C10: US-002 | D10: Réinitialisation du mot de passe | E10: Tout profil | F10: Un compte actif. | G10: 1. « Mot de passe oublié » : saisir l'e-mail. 2. Utiliser le lien reçu pour définir un nouveau mot de passe. 3. Se reconnecter avec l'ancien, puis le nouveau. 4. Demander la réinitialisation d'une adresse inconnue. | H10: L'ancien mot de passe est refusé, le nouveau accepté. L'adresse inconnue reçoit la même réponse neutre. Les sessions ouvertes sont fermées. | I10: Fonctionnel | J10: M | K10: Livré | L10: AuthEtUtilisateursTest | M10: À tester
A11: TC-ADM-007 | B11: ADM Administration | C11: US-003, EF-ADM-03 | D11: Régler les permissions d'un rôle action par action | E11: Administrateur | F11: Un rôle personnalisé et un utilisateur qui le porte, connecté. | G11: 1. Utilisateurs > Rôles : retirer une permission du rôle (par exemple « Transferts : valider »). 2. Enregistrer. 3. Côté utilisateur : constater la fermeture de session, se reconnecter. 4. Tenter l'action retirée par l'écran, puis par un appel direct à l'API (outil de test HTTP). | H11: Le bouton disparaît, l'appel direct à l'API répond 403. La modification est tracée avec les droits avant et après. La Direction est notifiée (cf. TC-ADM-015). | I11: Droits et périmètre | J11: M | K11: Livré | L11: RolesEtPermissionsTest | M11: À tester
A12: TC-ADM-008 | B12: ADM Administration | C12: EF-ADM-03, SRS 9.1 | D12: Matrice de départ des rôles conforme au SRS | E12: Administrateur | F12: Base neuve (rôles livrés par défaut). | G12: 1. Ouvrir chaque rôle livré (Administrateur, Direction, Responsable commercial, Commercial, Comptabilité/Caisse, Magasin, Contrôleur, Boutique). 2. Comparer ses permissions à la matrice de la section 9.1 du SRS (L, C, V, CV, T). | H12: Chaque rôle porte exactement les droits de la matrice. Les permissions spéciales (prix d'achat, stock modifier, stock bloquer, importer le stock initial, retour arrière commande…) sont attribuées aux rôles prévus. | I12: Droits et périmètre | J12: M | K12: Livré | L12: RolesEtPermissionsTest | M12: À tester
A13: TC-ADM-009 | B13: ADM Administration | C13: US-004, EF-ADM-08 | D13: Créer magasins et boutiques, fixer le mode de chaque boutique | E13: Administrateur | F13: Un magasin existe. | G13: 1. Emplacements > Nouveau : créer une boutique en mode A. 2. Créer une boutique en mode B sans magasin de rattachement. 3. Créer une boutique en mode B avec rattachement. 4. Vérifier que l'emplacement de transit interne existe et n'est pas modifiable. | H13: Le mode A est accepté. Le mode B sans rattachement est refusé. Le transit interne est géré par le système (ni modifiable, ni désactivable). | I13: Fonctionnel | J13: M | K13: Livré | L13: EmplacementsTest | M13: À tester
A14: TC-ADM-010 | B14: ADM Administration | C14: US-004, EF-ADM-08, EF-ADM-09 | D14: Changement de mode et désactivation refusés s'il reste du stock | E14: Administrateur | F14: Une boutique avec au moins une moto disponible. | G14: 1. Tenter de passer la boutique du mode A au mode B. 2. Tenter de la désactiver. 3. Faire livrer ou transférer toutes ses motos, puis recommencer. | H14: Avec du stock (ou un transfert/une réception en cours), les deux opérations sont refusées avec un motif. Sans stock, elles passent. | I14: Règle de gestion | J14: M | K14: Livré | L14: EmplacementsTest, StockTest | M14: À tester
A15: TC-ADM-011 | B15: ADM Administration | C15: US-005, EF-ADM-05, EF-ADM-06 | D15: Paramétrer seuils et délais de contrôle avec date d'effet | E15: Administrateur | F15: Aucun paramètre fiscal ni de contrôle renseigné. | G15: 1. Paramètres > Paramètres de contrôle : renseigner « Délai de réception d'un transfert » = 5 jours, date d'effet aujourd'hui. 2. Programmer une autre valeur à une date future. 3. Consulter l'historique du paramètre. 4. Saisir une valeur hors bornes ou non numérique. | H15: La valeur s'applique aux contrôles suivants. La future valeur n'est pas appliquée avant sa date. L'historique conserve ancienne et nouvelle valeur, auteur et date. Les valeurs invalides sont refusées. Tant qu'un seuil n'est pas fixé, le contrôle correspondant n'est pas appliqué. | I15: Fonctionnel | J15: M | K15: Livré | L15: ReferentielsEtParametresTest | M15: À tester
A16: TC-ADM-012 | B16: ADM Administration | C16: EF-REC-05, EF-TRF-05, RG-19 | D16: Paramètres de séparation des tâches (Oui par défaut) | E16: Administrateur | F16: Paramètres de contrôle affichés. | G16: 1. Vérifier « Réception validée par un autre utilisateur » et « Transfert réceptionné par un autre utilisateur » : valeur par défaut Oui, sans « À renseigner ». 2. Passer l'un à Non, rejouer TC-REC-006 ou TC-TRF-005, puis remettre Oui. | H16: Le défaut est Oui et ne compte pas dans l'avancement du paramétrage. À Non, la même personne peut valider ; la modification est historisée. | I16: Règle de gestion | J16: M | K16: Livré | L16: ReceptionsTest, TransfertsTest | M16: À tester
... A22: TC-ADM-018 | B22: ADM Administration | C22: TDB, EF-STK-10 | D22: Tableaux de bord par domaine et droits d'accès | E22: Direction, Magasinier, Commercial, Administrateur | F22: Un compte par profil. | G22: 1. Se connecter successivement avec chaque profil. 2. Observer le menu « Tableau de bord » et la page d'arrivée. 3. Tenter d'ouvrir par l'adresse un tableau de bord non autorisé et l'API correspondante. | H22: Management, Commercial et Administration sont trois pages séparées, chacune visible selon son droit. Un droit absent renvoie à une page autorisée (ou à l'accueil) et l'API répond 403. Les chiffres suivent le périmètre de la personne. | I22: Droits et périmètre | J22: M | K22: Livré | L22: TableauDeBordMetierTest, ReferentielsEtParametresTest | M22: À tester
A23: TC-ADM-019 | B23: ADM Administration | C23: SRS 14.5 | D23: Menu filtré par permissions | E23: Boutique, Magasin, Direction | F23: Comptes de chaque profil. | G23: 1. Comparer les entrées de menu affichées pour chaque profil. | H23: Un groupe de menu disparaît quand aucune de ses entrées n'est accessible. Aucune entrée ne mène à un écran interdit. | I23: Droits et périmètre | J23: S | K23: Livré | M23: À tester
A24: TC-ADM-020 | B24: ADM Administration | C24: AUD-01 à AUD-03, US-155 | D24: Journal d'audit en ajout seul | E24: Administrateur, équipe technique | F24: Plusieurs opérations déjà effectuées (réception validée, transfert expédié, blocage de châssis, import). | G24: 1. Tableau de bord Administration > Activité récente : lire les dernières actions. 2. En base (table journal_audit), retrouver l'opération : action, auteur, date, valeurs avant/après, motif. 3. En base, tenter un UPDATE puis un DELETE sur le journal, sur les mouvements de stock et sur l'historique des prix. 4. Vérifier la continuité du chaînage de hachage. | H24: Chaque ligne porte auteur, date, action, objet, valeurs avant/après et motif. Les écritures de modification ou de suppression sont refusées par la base (déclencheur). Le chaînage reste intact. L'écran complet du journal d'audit n'est pas livré dans ce lot (voir limites). | I24: Audit et traçabilité | J24: M | K24: Partiel | L24: JournalAuditTest | M24: À tester
A25: TC-ADM-021 | B25: ADM Administration | C25: EF-ADM-11, SRS 10.9 | D25: Session : persistance, déconnexion, suspension et changement de rôle | E25: Administrateur et utilisateur de test | F25: Un compte actif connecté dans un navigateur. | G25: 1. Naviguer entre plusieurs écrans : la connexion persiste. 2. Se déconnecter : la session et l'accès à l'API sont fermés. 3. En administrateur : suspendre le compte connecté. 4. Reconnecter le compte, puis changer ses rôles par l'administrateur. 5. Revenir sur le navigateur du compte. | H25: L'état de connexion survit aux requêtes et prend fin à la déconnexion. Une suspension ou un changement de rôle ferme la session immédiatement pour que les droits s'appliquent à la prochaine connexion. Une écriture sans jeton CSRF est refusée. | I25: Fonctionnel | J25: S | K25: Livré | L25: AuthEtUtilisateursTest, SecuriteTest | M25: À tester
A26: TC-CAT-001 | B26: CAT Catalogue et châssis | C26: US-010, EF-CAT-01 | D26: Créer un modèle avec ses prix | E26: Responsable commercial | F26: Aucun modèle de code CG125-2026. | G26: 1. Catalogue > Modèles > Nouveau. 2. Saisir marque, modèle, code article CG125-2026, format de châssis (expression), prix de vente 1 250 000, prix minimum 1 150 000. 3. Enregistrer. 4. Tenter de créer un second modèle avec le même code (casse différente). 5. Tenter un prix minimum supérieur au prix de vente. | H26: Le modèle est créé avec son prix à la date du jour. Le code article est unique sans tenir compte de la casse. Le prix minimum ne peut dépasser le prix de vente. | I26: Fonctionnel | J26: M | K26: Livré | L26: CatalogueTest | M26: À tester
A27: TC-CAT-002 | B27: CAT Catalogue et châssis | C27: US-011, EF-CAT-02 | D27: Changer un prix avec une date d'effet et consulter l'historique | E27: Responsable commercial | F27: Un modèle existant avec un prix de vente. | G27: 1. Fiche modèle > Changer le prix : nouveau prix, date d'effet dans 10 jours, motif. 2. Constater que le prix en vigueur est inchangé et que le prix est « programmé ». 3. Consulter l'historique des prix. 4. Tenter de saisir une date d'effet passée. | H27: Le prix programmé s'applique à sa date. L'historique (ajout seul) conserve chaque valeur, date d'effet, auteur et motif. Une date passée est refusée. | I27: Fonctionnel | J27: M | K27: Livré | L27: CatalogueTest | M27: À tester
A28: TC-CAT-003 | B28: CAT Catalogue et châssis | C28: US-011, EF-CAT-03 | D28: Baisser le prix minimum exige la validation catalogue | E28: Commercial / Responsable commercial | F28: Un modèle ; un compte avec « catalogue : modifier » mais sans « catalogue : valider ». | G28: 1. Sans le droit valider : baisser le prix minimum. 2. Avec le droit valider (Direction) : baisser le prix minimum. 3. Vérifier que min ≤ vente sur toute la chronologie (y compris prix programmés). | H28: Sans le droit, la baisse est refusée. Avec le droit, elle passe et est tracée. L'invariant minimum ≤ vente tient sur l'ensemble des prix passés et futurs. | I28: Règle de gestion | J28: M | K28: Livré | L28: CatalogueTest | M28: À tester
A29: TC-CAT-004 | B29: CAT Catalogue et châssis | C29: US-011 | D29: Les commandes déjà validées gardent leur prix | E29: Commercial | F29: Module des commandes clients (lot 2). | G29: 1. Valider une commande à un prix. 2. Changer le prix du modèle. 3. Rouvrir la commande. | H29: La commande conserve le prix validé. À rejouer à la recette du lot 2 : l'historique des prix est livré, le raccordement aux commandes arrive avec elles. | I29: Règle de gestion | J29: M | K29: À livrer | M29: Non livré
A30: TC-CAT-005 | B30: CAT Catalogue et châssis | C30: EF-CAT-08, SRS 9.2 | D30: Visibilité des prix d'achat selon permission | E30: Acheteur, Commercial | F30: Un modèle avec un prix d'achat de référence. | G30: 1. En commercial (sans « prix d'achat : voir ») ouvrir la fiche modèle et la liste des châssis. 2. En acheteur/Direction, refaire. 3. Interroger l'API de détail modèle avec chaque compte. | H30: Sans le droit, prix d'achat et coût de revient sont absents des écrans, des exports et des réponses API (champ masqué, pas seulement caché). Avec le droit ils apparaissent. | I30: Droits et périmètre | J30: M | K30: Livré | L30: CatalogueTest, ChassisTest | M30: À tester
A31: TC-CAT-006 | B31: CAT Catalogue et châssis | C31: US-012, EF-CAT-05 | D31: Fiche châssis : toute l'histoire d'une moto | E31: Magasinier, Direction | F31: Une moto passée par colisage, réception, transfert et un blocage. | G31: 1. Stock > Châssis (ou Catalogue > Châssis) : rechercher le numéro. 2. Ouvrir la fiche. 3. Lire la chronologie. 4. Se connecter en magasinier sans « prix d'achat : voir » et vérifier le coût. | H31: La fiche affiche statut, emplacement, date d'entrée, ancienneté et chaque événement daté avec son auteur et ses statuts avant/après (création, arrivée, réception, expédition, réception de transfert, blocage…). Le coût est masqué sans la permission. | I31: Fonctionnel | J31: M | K31: Livré | L31: ChassisTest | M31: À tester
A32: TC-CAT-007 | B32: CAT Catalogue et châssis | C32: US-013, EF-CAT-07 | D32: Corriger un numéro de châssis avec validation d'un collègue | E32: Responsable magasin (demandeur), Magasinier 2 (valideur) | F32: Un châssis au numéro mal saisi. | G32: 1. Fiche châssis > Corriger avec autorisation : nouveau numéro et motif. 2. Constater la demande « en attente ». 3. Tenter de la valider avec le même utilisateur. 4. La valider avec un second utilisateur. 5. Rechercher l'ancien numéro. | H32: Le demandeur ne peut pas valider sa propre demande. Après validation le châssis porte le nouveau numéro, l'ancien reste trouvable et affiché sur la fiche. Un refus exige un motif. Tout est au journal. | I32: Règle de gestion | J32: M | K32: Livré | L32: ChassisTest | M32: À tester
A33: TC-CAT-008 | B33: CAT Catalogue et châssis | C33: US-013 | D33: Correction refusée si le châssis figure sur une facture normalisée | E33: Responsable magasin | F33: Module de facturation (lot 2). | G33: 1. Facturer un châssis (facture normalisée). 2. Demander la correction de son numéro. | H33: La demande est refusée. Le point d'extension existe côté châssis ; la règle s'active avec le module de facturation (lot 2). | I33: Règle de gestion | J33: M | K33: À livrer | M33: Non livré
A34: TC-CAT-009 | B34: CAT Catalogue et châssis | C34: EF-CAT-04, EF-CAT-06 | D34: Liste des châssis : recherche, filtres, export | E34: Direction, Magasinier | F34: Une centaine de châssis de statuts variés. | G34: 1. Filtrer par statut, modèle, emplacement, ancienneté minimale (30/60/90/180 jours). 2. Rechercher par fragment de numéro, de moteur, ou par ancien numéro corrigé. 3. Exporter la liste filtrée (CSV) avec puis sans le droit d'export. | H34: Les filtres se combinent et se retrouvent dans l'adresse (liens depuis le stock). L'export respecte le périmètre et les colonnes autorisées, et est tracé au journal. Sans le droit : refusé. | I34: Fonctionnel | J34: S | K34: Livré | L34: ChassisTest | M34: À tester
A35: TC-CAT-010 | B35: CAT Catalogue et châssis | C35: RG-01, EF-CAT-04 | D35: Unicité du numéro de châssis (casse, tirets, espaces ignorés) | E35: Magasinier | F35: Un châssis LWBAB12CD34EF56GH en stock. | G35: 1. Tenter de le recréer via la réception avec la saisie « lwb-ab12 cd34-ef56gh ». 2. Tenter de l'importer dans un fichier de stock initial. 3. Tenter de le scanner comme moto non annoncée. | H35: Chaque tentative est refusée comme doublon avec l'emplacement actuel de la moto. Un seul châssis existe par numéro normalisé (index unique en base). | I35: Règle de gestion | J35: M | K35: Livré | L35: ChassisTest, ReceptionsTest, StockInitialTest | M35: À tester
A36: TC-APP-001 | B36: APP Approvisionnements | C36: US-020, EF-APP-01 | D36: Créer une commande fournisseur | E36: Acheteur | F36: Un fournisseur actif et un modèle avec prix d'achat. | G36: 1. Approvisionnements > Commandes > Nouvelle. 2. Fournisseur, devise USD, taux de change 600, incoterm FOB, base de prix FOB, lignes : modèle A × 3 à 1 000 USD, modèle B × 2 à 800 USD. 3. Enregistrer. 4. Consulter le stock avant/après. | H36: La commande est créée au statut COMMANDÉE avec son numéro PO-. Le stock ne change pas (RG-06). Le total est calculé en devise et en FCFA. La Direction est notifiée. La commande est au journal. | I36: Fonctionnel | J36: M | K36: Livré | L36: CommandesFournisseurTest | M36: À tester
A37: TC-APP-002 | B37: APP Approvisionnements | C37: US-021, EF-APP-02 | D37: Faire avancer la commande d'étape en étape | E37: Acheteur | F37: Une commande COMMANDÉE. | G37: 1. Avancer vers CONFIRMÉE (référence proforma). 2. Tenter de passer directement à AU PORT. 3. Avancer étape par étape jusqu'à la fin permise. 4. Consulter l'historique de la commande. | H37: Chaque étape enregistre date et auteur. Une étape sautée est refusée. Les étapes « Réception partielle » et « Réceptionnée » ne s'avancent jamais à la main. | I37: Règle de gestion | J37: M | K37: Livré | L37: CommandesFournisseurTest | M37: À tester
A38: TC-APP-003 | B38: APP Approvisionnements | C38: EF-APP-02, EF-APP-04 | D38: Étapes de la commande conditionnées par l'arrivage | E38: Acheteur | F38: Une commande confirmée avec un arrivage. | G38: 1. Tenter « Dédouanement » alors qu'aucun dédouanement n'est démarré. 2. Tenter « Au port » sans date d'arrivée réelle. 3. Saisir la date d'arrivée, démarrer puis terminer le dédouanement de l'arrivage. 4. Avancer la commande à « À réceptionner ». | H38: Chaque passage est refusé tant que la condition n'est pas remplie, avec un message qui dit laquelle. Quand le dédouanement est terminé, les motos annoncées passent « À réceptionner » et le magasin est notifié. | I38: Règle de gestion | J38: M | K38: Livré | L38: ArrivagesTest, CommandesFournisseurTest | M38: À tester
A39: TC-APP-004 | B39: APP Approvisionnements | C39: US-020, SRS 9.3 | D39: Retour arrière de statut : droit spécifique | E39: Acheteur, Direction | F39: Une commande à une étape avancée. | G39: 1. En acheteur : tenter un retour arrière. 2. En Direction (droit « retour arrière ») : faire un retour arrière avec motif. | H39: Refusé sans le droit. Avec le droit, motif obligatoire, historisé. | I39: Droits et périmètre | J39: S | K39: Livré | L39: CommandesFournisseurTest | M39: À tester
A40: TC-APP-005 | B40: APP Approvisionnements | C40: US-022, EF-APP-03 | D40: Saisir les frais d'un arrivage avec leurs pièces | E40: Acheteur | F40: Un arrivage rattaché à une commande. | G40: 1. Arrivage > Frais > Ajouter : type Fret, 1 200 USD, taux 600, sans pièce. 2. Ajouter un frais en FCFA avec pièce. 3. Annuler un frais avec motif. 4. Consulter le coût provisoire de la commande. | H40: Le montant FCFA est arrondi selon la règle et recalculé. Le frais sans pièce est signalé (alerte). L'annulation exige un motif et reste visible. Le coût de revient provisoire par moto est recalculé. | I40: Fonctionnel | J40: M | K40: Livré | L40: ArrivagesTest | M40: À tester
A41: TC-APP-006 | B41: APP Approvisionnements | C41: US-023, EF-APP-06 | D41: Importer la liste de colisage (CSV et Excel) | E41: Acheteur | F41: Un arrivage et deux fichiers : un CSV et un XLSX de colisage (10 lignes dont 2 fautives : un doublon, un code article inconnu). | G41: 1. Arrivage > Colisage : charger le fichier en mode simulation. 2. Lire le rapport. 3. Relancer sans simulation. 4. Recharger le même fichier. | H41: La simulation ne crée rien. L'import crée les châssis « En transit fournisseur » (hors stock) avec leur arrivage ; les lignes fautives sont rejetées avec numéro de ligne et motif. Le second import ne crée aucun doublon. La quantité cumulée ne peut dépasser la commande. | I41: Fonctionnel | J41: S | K41: Livré | L41: ArrivagesTest | M41: À tester
A42: TC-APP-007 | B42: APP Approvisionnements | C42: EF-APP-09 | D42: Suivi des arrivages : retard, état dérivé | E42: Acheteur, Direction | F42: Un arrivage avec date d'arrivée prévue dépassée et non arrivé. | G42: 1. Approvisionnements > Arrivages en cours. 2. Constater l'état et le retard en jours. 3. Saisir la date d'arrivée réelle. | H42: L'état est calculé (en transit, au port, dédouanement, à réceptionner) et le retard s'affiche tant que la marchandise n'est pas arrivée. Le tableau de bord Management le reprend. | I42: Fonctionnel | J42: S | K42: Livré | L42: ArrivagesTest, TableauDeBordMetierTest | M42: À tester
A43: TC-APP-008 | B43: APP Approvisionnements | C43: SRS 9.2 | D43: Droits du module : acheteur, magasin, contrôleur | E43: Magasinier, Contrôleur | F43: Une commande existante. | G43: 1. En magasinier : ouvrir les commandes. 2. Tenter de créer une commande et de voir les prix d'achat. | H43: Lecture seule pour le magasin et le contrôleur. La création est refusée côté API. Les prix sont masqués sans « prix d'achat : voir » (ou « approvisionnements : créer » pour les prix de commande). | I43: Droits et périmètre | J43: M | K43: Livré | L43: CommandesFournisseurTest | M43: À tester
A44: TC-REC-001 | B44: REC Réceptions | C44: EF-REC-01 | D44: Ouvrir une réception depuis un arrivage dédouané | E44: Magasinier | F44: Une commande « À réceptionner », un arrivage dédouané avec colisage, un magasin dans le périmètre. | G44: 1. Stock > Réceptions : l'arrivage apparaît dans « Arrivages à réceptionner ». 2. Cliquer Réceptionner. 3. Retourner à la liste et recliquer sur le même arrivage. 4. Tenter d'ouvrir une réception sur un arrivage non dédouané. | H44: Une réception BROUILLON est créée avec son numéro. Une seule réception ouverte par arrivage (le bouton devient « Reprendre »). Un arrivage non dédouané est refusé. Le lieu de réception est un magasin actif du périmètre. | I44: Fonctionnel | J44: M | K44: Livré | L44: ReceptionsTest | M44: À tester
A45: TC-REC-002 | B45: REC Réceptions | C45: US-024, EF-REC-02, EF-REC-03 | D45: Scanner les châssis reçus : contrôles à la saisie | E45: Magasinier | F45: Une réception ouverte pour un colisage de 3 motos modèle A et 1 moto modèle B. | G45: 1. Scanner un châssis annoncé (saisie en minuscules avec tirets). 2. Rescanner le même. 3. Scanner un numéro au mauvais format du modèle. 4. Scanner un châssis déjà en stock ailleurs. 5. Scanner un châssis d'un autre modèle que celui annoncé. 6. Scanner 20 numéros d'affilée très vite (lecteur). | H45: Chaque contrôle affiche son message (doublon, format, déjà en stock, modèle différent). Aucun scan n'est perdu lors d'une saisie rapide. Le compteur attendu / reçu / écart par modèle suit en continu. | I45: Fonctionnel | J45: M | K45: Livré | L45: ReceptionsTest | M45: À tester
...

Sheet Recette Lot 1
A1: Scénarios de recette de bout en bout — Lot 1
A2: Chaque scénario se joue dans l'ordre, avec des comptes distincts quand le profil change. Renseigner Résultat, Date, Testeur et la preuve (capture d'écran, n° de document).
A4: Scénario | B4: Étape | C4: Action | D4: Profil | E4: Résultat attendu | F4: Réf. SRS | G4: Résultat | H4: Date | I4: Testeur | J4: Preuve / commentaire
A5: RV1-01 · Reprise du stock d'un site : import puis pointage à écart nul (jalon V1)
A6: RV1-01 | B6: 1 | C6: Créer le magasin, la boutique pilote et vérifier les modèles au catalogue. | D6: Administrateur | E6: Emplacements et modèles disponibles, prix renseignés. | F6: SRS 14.2 | G6: À faire
A7: RV1-01 | B7: 2 | C7: Remplir le modèle Excel avec l'inventaire d'ouverture du magasin (≥ 50 motos) et lancer la simulation. | D7: Administrateur | E7: Rapport sans rien créer ; les lignes fautives sont listées avec leur motif. | F7: SRS 14.2 | G7: À faire
A8: RV1-01 | B8: 3 | C8: Corriger le fichier et importer pour de bon. | D8: Administrateur | E8: Toutes les motos sont au stock du magasin ; le rapport est conservé. | F8: SRS 14.2 | G8: À faire
A9: RV1-01 | B9: 4 | C9: Compter physiquement le magasin au scan et pointer. | D9: Magasinier | E9: Rapport de rapprochement : manquants et inattendus identifiés. | F9: SRS 14.2 | G9: À faire
A10: RV1-01 | B10: 5 | C10: Traiter les écarts (corriger le fichier ou le comptage) et pointer de nouveau. | D10: Magasinier | E10: Écart nul : stock d'ouverture validé pour le site. | F10: SRS 14.2 | G10: À faire
A11: RV1-01 | B11: 6 | C11: Répéter pour la boutique pilote puis pour la seconde boutique. | D11: Vendeur boutique | E11: Écart nul sur chacun des sites. | F11: SRS 14.2 | G11: À faire
A12: RV1-02 · R1 (partie lot 1) : commande fournisseur, colisage, dédouanement, réception de 100 châssis
A13: RV1-02 | B13: 1 | C13: Créer une commande fournisseur de 100 motos (plusieurs modèles). | D13: Acheteur | E13: Statut COMMANDÉE, stock inchangé. | F13: R1 (partiel) | G13: À faire
A14: RV1-02 | B14: 2 | C14: Confirmer, importer le colisage de 100 lignes, saisir arrivée, frais avec pièces. | D14: Acheteur | E14: 100 châssis « En transit fournisseur » ; coût provisoire calculé ; frais sans pièce signalé. | F14: R1 (partiel) | G14: À faire
A15: RV1-02 | B15: 3 | C15: Terminer le dédouanement de l'arrivage et avancer la commande. | D15: Acheteur | E15: Commande « À réceptionner » ; châssis « À réceptionner » ; magasin notifié. | F15: R1 (partiel) | G15: À faire
A16: RV1-02 | B16: 4 | C16: Ouvrir la réception et scanner les 100 châssis. | D16: Magasinier | E16: Compteurs attendu/reçu/écart à jour sans scan perdu. | F16: R1 (partiel) | G16: À faire
A17: RV1-02 | B17: 5 | C17: Valider la réception par un second utilisateur. | D17: Responsable magasin | E17: Stock physique du magasin +100, 100 disponibles, mouvements écrits, PV généré, commande « Réceptionnée ». | F17: R1 (partiel) | G17: À faire
A18: RV1-02 | B18: 6 | C18: Contrôler le stock global et la fiche de 3 châssis. | D18: Direction | E18: 100 physiques, 100 disponibles ; historiques complets. (La suite R1 — commande client, facture, livraison — se joue au lot 2.) | F18: R1 (partiel) | G18: À faire
A19: RV1-03 · R6 : transfert de 10 motos dont 9 reçues
A20: RV1-03 | B20: 1 | C20: Créer un transfert de 10 motos du magasin vers la boutique. | D20: Magasinier | E20: Transfert « Initié », stock inchangé. | F20: R6 | G20: À faire
A21: RV1-03 | B21: 2 | C21: Expédier le transfert et éditer le bon. | D21: Responsable magasin | E21: Stock source −10 ; 10 motos « En transit interne » ; bon PDF ; boutique notifiée. | F21: R6 | G21: À faire
A22: RV1-03 | B22: 3 | C22: Réceptionner par pointage 9 motos, clôturer avec écart. | D22: Vendeur boutique | E22: 9 motos en stock à la destination ; 1 en transit interne. | F22: R6 | G22: À faire
A23: RV1-03 | B23: 4 | C23: Consulter l'anomalie et les notifications. | D23: Contrôleur | E23: Anomalie A12 ouverte avec le coût de la moto manquante ; alerte reçue. | F23: R6 | G23: À faire
A24: RV1-03 | B24: 5 | C24: Contrôler la fiche de la moto manquante et le stock global. | D24: Direction | E24: Moto « En transit interne » comptée une seule fois dans le global. | F24: R6 | G24: À faire
A25: RV1-04 · R10 (partie lot 1) : contrôle des droits et du périmètre
A26: RV1-04 | B26: 1 | C26: Se connecter en commercial : ouvrir catalogue, stock, fiche châssis. | D26: Commercial | E26: Aucun coût de revient ni prix d'achat visible, ni sur l'écran ni par l'API. | F26: R10 (partiel) | G26: À faire
A27: RV1-04 | B27: 2 | C27: Se connecter en magasinier d'un site : consulter le stock, un transfert, une réception d'un autre site. | D27: Magasinier | E27: Seul son périmètre est visible ; les objets d'un autre site sont introuvables. | F27: R10 (partiel) | G27: À faire
A28: RV1-04 | B28: 3 | C28: Se connecter en contrôleur : tenter de modifier un stock, de valider une réception. | D28: Contrôleur | E28: Lecture seule sur ces modules ; blocage et corrections selon ses droits spécifiques. | F28: R10 (partiel) | G28: À faire
A29: RV1-04 | B29: 4 | C29: Retirer un droit à un rôle et refaire l'action par un appel direct à l'API. | D29: Administrateur | E29: Refus 403 ; modification tracée ; Direction notifiée. | F29: R10 (partiel) | G29: À faire
A30: RV1-05 · Réception en plusieurs fois, avec moto endommagée et moto non annoncée
A31: RV1-05 | B31: 1 | C31: Ouvrir une réception d'un arrivage de 5 motos annoncées ; scanner 3 conformes, 1 endommagée, 1 non annoncée. | D31: Magasinier | E31: Messages de contrôle à chaque cas ; justification et description exigées. | F31: REC, STK | G31: À faire
A32: RV1-05 | B32: 2 | C32: Valider par un second utilisateur. | D32: Responsable magasin | E32: 2 disponibles, 1 bloquée, 1 inattendue disponible ; commande « Réception partielle » avec reliquat ; contrôleur notifié. | F32: REC, STK | G32: À faire
A33: RV1-05 | B33: 3 | C33: Recevoir le reliquat dans une seconde réception. | D33: Magasinier | E33: Commande « Réceptionnée » quand tout est reçu ; deux PV distincts. | F33: REC, STK | G33: À faire
A34: RV1-05 | B34: 4 | C34: Bloquer puis débloquer une moto en litige. | D34: Responsable magasin | E34: Motif et pièce exigés ; historique de la fiche à jour. | F34: REC, STK | G34: À faire
A35: RV1-06 · Correction d'un numéro de châssis et traçabilité complète d'une moto
A36: RV1-06 | B36: 1 | C36: Demander la correction d'un numéro mal saisi. | D36: Responsable magasin | E36: Demande « en attente ». | F36: US-013, US-012 | G36: À faire
A37: RV1-06 | B37: 2 | C37: Tenter de la valider avec le même compte puis avec un collègue. | D37: Responsable magasin, Magasinier | E37: Refus puis validation ; l'ancien numéro reste trouvable. | F37: US-013, US-012 | G37: À faire
A38: RV1-06 | B38: 3 | C38: Ouvrir la fiche : lire l'histoire depuis la création à la réception puis au transfert. | D38: Direction | E38: Chaque événement daté, avec auteur et statuts avant/après. | F38: US-013, US-012 | G38: À faire
A39: RV1-06 | B39: 4 | C39: Rechercher la moto par l'ancien numéro. | D39: Magasinier | E39: La fiche s'ouvre ; l'ancien numéro est signalé. | F39: US-013, US-012 | G39: À faire
A40: RV1-07 · Séparation des tâches et non-suppression
A41: RV1-07 | B41: 1 | C41: Même utilisateur : ouvrir et valider une réception ; expédier et réceptionner un transfert. | D41: Magasinier | E41: Refus dans les deux cas (paramètres à Oui). | F41: RG-18, RG-19 | G41: À faire
...

Sheet Reprise des données
A1: Reprise des données — Lot 1
A2: Source : SRS 14.2. La bascule se fait site par site : le magasin et une boutique pilote d'abord, la seconde boutique deux semaines plus tard.
A4: Donnée | B4: Source | C4: Méthode | D4: Contrôle de validation | E4: Responsable | F4: Outil livré / remarque | G4: Statut | H4: Date de validation | I4: Validé par
A5: Modèles et prix | B5: Fichiers commerciaux | C5: Import Excel (saisie à l'écran en attendant) | D5: Relecture par le responsable commercial | E5: Responsable commercial | F5: Les modèles se créent un à un à l'écran dans ce lot ; l'import en masse des modèles n'est pas livré. | G5: À faire
A6: Stock par châssis | B6: Inventaire physique d'ouverture, par scan | C6: Import Excel (Stock > Import du stock initial) puis pointage | D6: Écart nul par site entre l'import et le comptage | E6: Magasinier + Administrateur | F6: Outils livrés : import avec simulation et rapport, pointage d'ouverture avec rapport conservé. | G6: À faire
A7: Arrivages en cours | B7: Dossiers d'importation | C7: Saisie (commandes, arrivages, colisage) | D7: Relecture par la Direction | E7: Acheteur | F7: Les commandes et arrivages en cours se saisissent à l'écran ; le colisage s'importe en CSV/Excel. | G7: À faire
A8: Utilisateurs, rôles et emplacements | B8: Organisation de VITRACO | C8: Saisie | D8: Validation par la Direction | E8: Administrateur | F8: Les 8 rôles livrés sont à ajuster ; le second facteur est à activer pour Administrateur, Direction et Comptabilité. | G8: À faire
A9: Fournisseurs et référentiels | B9: Fichiers commerciaux et comptables | C9: Saisie | D9: Relecture par la comptabilité | E9: Administrateur | F9: Fournisseurs, banques, modes de paiement, catégories de dépense, centres de coût. | G9: À faire
A10: Paramètres de contrôle et fiscaux | B10: Direction et comptabilité | C10: Saisie (Paramètres) | D10: Validation par la Direction | E10: Direction | F10: Les seuils et délais non fixés désactivent le contrôle correspondant ; taux fiscaux à confirmer avec la DGI. | G10: À faire
A13: Rapprochement du stock d'ouverture, site par site
A14: Reporter ici, pour chaque site, les chiffres du dernier rapport de l'écran Stock > Pointage d'ouverture. « Écart nul » est calculé : il faut zéro manquant et zéro inattendu avec un pointage renseigné.
A16: Site | B16: Type | C16: Date de l'import | D16: Motos importées | E16: Motos pointées | F16: Manquantes | G16: Inattendues | H16: Écart nul ? | I16: Validé par la Direction
A17: Magasin principal | B17: Magasin | H17: =IF(AND(E17<>"",F17=0,G17=0),"Oui","Non")
A18: Boutique pilote | B18: Boutique | H18: =IF(AND(E18<>"",F18=0,G18=0),"Oui","Non")
A19: Seconde boutique (J+14) | B19: Boutique | H19: =IF(AND(E19<>"",F19=0,G19=0),"Oui","Non")
A21: Rappel : le pointage ne corrige rien. Un écart se traite en corrigeant le fichier d'import (puis en réimportant les seules lignes manquantes) ou, en production, par un ajustement validé par un second utilisateur (module des ajustements, lot ultérieur).

Sheet Jeu de données import
A1: Jeu de données — import du stock initial (TC-REP-001, TC-REP-002)
A2: Recopier ces lignes dans le modèle Excel (Stock > Import du stock initial > Télécharger le modèle), après avoir remplacé les valeurs entre chevrons.
A4: Cas | B4: numero_chassis | C4: code_article | D4: emplacement | E4: statut | F4: date_entree | G4: cout_revient | H4: motif_blocage | I4: Résultat attendu
A5: Ligne valide, avec date, coût et couleur | B5: LWBTEST00000000001 | C5: <CODE_ARTICLE> | D5: <CODE_MAGASIN> | E5: disponible | F5: 01/09/2026 | G5: 980000 | I5: Importée
A6: Ligne valide, valeurs par défaut | B6: LWBTEST00000000002 | C6: <CODE_ARTICLE> | D6: <CODE_BOUTIQUE> | I6: Importée (statut disponible, date du jour)
A7: Moto bloquée avec motif | B7: LWBTEST00000000003 | C7: <CODE_ARTICLE> | D7: <CODE_MAGASIN> | E7: bloqué | H7: Cadre fissuré | I7: Importée BLOQUÉE avec son motif
A8: Emplacement donné par son nom | B8: LWBTEST00000000004 | C8: <CODE_ARTICLE> | D8: <NOM_BOUTIQUE> | G8: 1 250 000 | I8: Importée (coût 1 250 000 lu malgré les espaces)
A9: Numéro avec tirets et minuscules | B9: lwb-test-0000-0000-05 | C9: <CODE_ARTICLE> | D9: <CODE_MAGASIN> | I9: Importée (numéro normalisé en majuscules sans tirets)
A10: Doublon dans le fichier | B10: LWBTEST00000000001 | C10: <CODE_ARTICLE> | D10: <CODE_MAGASIN> | I10: Rejetée : doublon dans le fichier
A11: Châssis déjà au stock | B11: <NUMERO_DEJA_EN_STOCK> | C11: <CODE_ARTICLE> | D11: <CODE_MAGASIN> | I11: Rejetée : châssis déjà enregistré (avec son emplacement)
A12: Code article inconnu | B12: LWBTEST00000000006 | C12: ZZ-INCONNU | D12: <CODE_MAGASIN> | I12: Rejetée : code article inconnu : ZZ-INCONNU
A13: Emplacement inconnu | B13: LWBTEST00000000007 | C13: <CODE_ARTICLE> | D13: LIEU-FANTOME | I13: Rejetée : emplacement inconnu, désactivé ou qui n'est ni un magasin ni une boutique
A14: Emplacement de transit | B14: LWBTEST00000000008 | C14: <CODE_ARTICLE> | D14: TRANSIT | I14: Rejetée : ni un magasin ni une boutique
A15: Bloqué sans motif | B15: LWBTEST00000000009 | C15: <CODE_ARTICLE> | D15: <CODE_MAGASIN> | E15: bloqué | I15: Rejetée : un châssis bloqué exige un motif
A16: Statut non repris | B16: LWBTEST00000000010 | C16: <CODE_ARTICLE> | D16: <CODE_MAGASIN> | E16: réservée | I16: Rejetée : statut non repris
A17: Date illisible | B17: LWBTEST00000000011 | C17: <CODE_ARTICLE> | D17: <CODE_MAGASIN> | F17: 31/02/2026 | I17: Rejetée : date d'entrée illisible
A18: Date dans le futur | B18: LWBTEST00000000012 | C18: <CODE_ARTICLE> | D18: <CODE_MAGASIN> | F18: <DATE_DEMAIN> | I18: Rejetée : date d'entrée dans le futur
A19: Coût négatif | B19: LWBTEST00000000013 | C19: <CODE_ARTICLE> | D19: <CODE_MAGASIN> | G19: -5 | I19: Rejetée : coût de revient négatif
A20: Format de châssis non conforme au modèle | B20: XX1 | C20: <CODE_ARTICLE> | D20: <CODE_MAGASIN> | I20: Rejetée : numéro ne respectant pas le format du modèle (si un format est défini)
A21: Numéro manquant | C21: <CODE_ARTICLE> | D21: <CODE_MAGASIN> | I21: Rejetée : numéro de châssis manquant
A22: Ligne entièrement vide | I22: Ignorée (ni importée, ni rejetée, non comptée)
A24: Remplacements : <CODE_ARTICLE> = un code article existant au catalogue ; <CODE_MAGASIN> et <CODE_BOUTIQUE> = codes d'emplacement existants (ou leur nom) ; <NOM_BOUTIQUE> = nom complet de la boutique ;
A25: <NUMERO_DEJA_EN_STOCK> = le numéro d'un châssis déjà au stock ; <DATE_DEMAIN> = la date de demain au format jj/mm/aaaa.
A26: Résultat attendu de l'ensemble : 5 lignes importées, 12 lignes rejetées avec leur motif, 1 ligne vide ignorée. Rejouer ensuite le fichier : 0 ligne importée (aucun doublon).
A27: Colonnes obligatoires : numero_chassis, code_article, emplacement. Facultatives : statut (disponible par défaut, ou bloqué avec motif), date_entree, cout_revient, numero_moteur, couleur, motif_blocage. Formats : .xlsx ou .csv (séparateur ; , ou tabulation).

Sheet Traçabilité
A1: Traçabilité — user stories du lot 1
A2: Le nombre de cas et leur résultat sont calculés à partir de l'onglet « Plan de test » (colonne Référence).
A4: Story | B4: Epic | C4: Intitulé | D4: Critères d'acceptation (SRS) | E4: Livraison | F4: Cas | G4: Réussis | H4: Échecs | I4: Reste | J4: Verdict | K4: Commentaire
A5: US-001 | B5: EP-01 | C5: Créer un utilisateur avec ses rôles et ses emplacements | D5: Lien d'activation ; ne voit que ses emplacements ; création au journal | E5: Livré | F5: =COUNTIF('Plan de test'!$C$5:$C$152,"*"&A5&"*") | G5: =COUNTIFS('Plan de test'!$C$5:$C$152,"*"&A5&"*",'Plan de test'!$M$5:$M$152,"Réussi") | H5: =COUNTIFS('Plan de test'!$C$5:$C$152,"*"&A5&"*",'Plan de test'!$M$5:$M$152,"Échec")+COUNTIFS('Plan de test'!$C$5:$C$152,"*"&A5&"*",'Plan de test'!$M$5:$M$152,"Bloqué") | I5: =F5-G5-H5-COUNTIFS('Plan de test'!$C$5:$C$152,"*"&A5&"*",'Plan de test'!$M$5:$M$152,"Non livré") | J5: =IF(F5=0,"Aucun cas",IF(H5>0,"Échec",IF(G5=F5,"Validée",IF(G5+COUNTIFS('Plan de test'!$C$5:$C$152,"*"&A5&"*",'Plan de test'!$M$5:$M$152,"Non livré")=F5,"Non livrée","En cours"))))
A6: US-002 | B6: EP-01 | C6: Connexion par mot de passe et second facteur | D6: 5 échecs verrouillent ; second facteur pour Administrateur, Direction, Comptabilité | E6: Livré | F6: =COUNTIF('Plan de test'!$C$5:$C$152,"*"&A6&"*") | G6: =COUNTIFS('Plan de test'!$C$5:$C$152,"*"&A6&"*",'Plan de test'!$M$5:$M$152,"Réussi") | H6: =COUNTIFS('Plan de test'!$C$5:$C$152,"*"&A6&"*",'Plan de test'!$M$5:$M$152,"Échec")+COUNTIFS('Plan de test'!$C$5:$C$152,"*"&A6&"*",'Plan de test'!$M$5:$M$152,"Bloqué") | I6: =F6-G6-H6-COUNTIFS('Plan de test'!$C$5:$C$152,"*"&A6&"*",'Plan de test'!$M$5:$M$152,"Non livré") | J6: =IF(F6=0,"Aucun cas",IF(H6>0,"Échec",IF(G6=F6,"Validée",IF(G6+COUNTIFS('Plan de test'!$C$5:$C$152,"*"&A6&"*",'Plan de test'!$M$5:$M$152,"Non livré")=F6,"Non livrée","En cours"))))
A7: US-003 | B7: EP-01 | C7: Régler les permissions d'un rôle action par action | D7: Retirer « Voir marges » masque les marges ; appel direct refusé | E7: Partiel | F7: =COUNTIF('Plan de test'!$C$5:$C$152,"*"&A7&"*") | G7: =COUNTIFS('Plan de test'!$C$5:$C$152,"*"&A7&"*",'Plan de test'!$M$5:$M$152,"Réussi") | H7: =COUNTIFS('Plan de test'!$C$5:$C$152,"*"&A7&"*",'Plan de test'!$M$5:$M$152,"Échec")+COUNTIFS('Plan de test'!$C$5:$C$152,"*"&A7&"*",'Plan de test'!$M$5:$M$152,"Bloqué") | I7: =F7-G7-H7-COUNTIFS('Plan de test'!$C$5:$C$152,"*"&A7&"*",'Plan de test'!$M$5:$M$152,"Non livré") | J7: =IF(F7=0,"Aucun cas",IF(H7>0,"Échec",IF(G7=F7,"Validée",IF(G7+COUNTIFS('Plan de test'!$C$5:$C$152,"*"&A7&"*",'Plan de test'!$M$5:$M$152,"Non livré")=F7,"Non livrée","En cours")))) | K7: Mécanisme livré et testé ; l'écran des marges viendra avec le lot 2
A8: US-004 | B8: EP-01 | C8: Créer magasins et boutiques, fixer le mode de chaque boutique | D8: Mode B exige un rattachement ; changement refusé s'il reste du stock | E8: Livré | F8: =COUNTIF('Plan de test'!$C$5:$C$152,"*"&A8&"*") | G8: =COUNTIFS('Plan de test'!$C$5:$C$152,"*"&A8&"*",'Plan de test'!$M$5:$M$152,"Réussi") | H8: =COUNTIFS('Plan de test'!$C$5:$C$152,"*"&A8&"*",'Plan de test'!$M$5:$M$152,"Échec")+COUNTIFS('Plan de test'!$C$5:$C$152,"*"&A8&"*",'Plan de test'!$M$5:$M$152,"Bloqué") | I8: =F8-G8-H8-COUNTIFS('Plan de test'!$C$5:$C$152,"*"&A8&"*",'Plan de test'!$M$5:$M$152,"Non livré") | J8: =IF(F8=0,"Aucun cas",IF(H8>0,"Échec",IF(G8=F8,"Validée",IF(G8+COUNTIFS('Plan de test'!$C$5:$C$152,"*"&A8&"*",'Plan de test'!$M$5:$M$152,"Non livré")=F8,"Non livrée","En cours")))) | K8: Contrôle du stock activé avec le lot 1
A9: US-005 | B9: EP-01 | C9: Paramétrer les seuils et délais de contrôle | D9: Nouvelle valeur applicable aux contrôles suivants ; ancienne au journal | E9: Livré | F9: =COUNTIF('Plan de test'!$C$5:$C$152,"*"&A9&"*") | G9: =COUNTIFS('Plan de test'!$C$5:$C$152,"*"&A9&"*",'Plan de test'!$M$5:$M$152,"Réussi") | H9: =COUNTIFS('Plan de test'!$C$5:$C$152,"*"&A9&"*",'Plan de test'!$M$5:$M$152,"Échec")+COUNTIFS('Plan de test'!$C$5:$C$152,"*"&A9&"*",'Plan de test'!$M$5:$M$152,"Bloqué") | I9: =F9-G9-H9-COUNTIFS('Plan de test'!$C$5:$C$152,"*"&A9&"*",'Plan de test'!$M$5:$M$152,"Non livré") | J9: =IF(F9=0,"Aucun cas",IF(H9>0,"Échec",IF(G9=F9,"Validée",IF(G9+COUNTIFS('Plan de test'!$C$5:$C$152,"*"&A9&"*",'Plan de test'!$M$5:$M$152,"Non livré")=F9,"Non livrée","En cours"))))
A10: US-006 | B10: EP-01 | C10: Importer les données initiales depuis Excel | D10: Lignes en erreur rejetées avec motif ; aucun doublon ; rapport d'import | E10: Partiel | F10: =COUNTIF('Plan de test'!$C$5:$C$152,"*"&A10&"*") | G10: =COUNTIFS('Plan de test'!$C$5:$C$152,"*"&A10&"*",'Plan de test'!$M$5:$M$152,"Réussi") | H10: =COUNTIFS('Plan de test'!$C$5:$C$152,"*"&A10&"*",'Plan de test'!$M$5:$M$152,"Échec")+COUNTIFS('Plan de test'!$C$5:$C$152,"*"&A10&"*",'Plan de test'!$M$5:$M$152,"Bloqué") | I10: =F10-G10-H10-COUNTIFS('Plan de test'!$C$5:$C$152,"*"&A10&"*",'Plan de test'!$M$5:$M$152,"Non livré") | J10: =IF(F10=0,"Aucun cas",IF(H10>0,"Échec",IF(G10=F10,"Validée",IF(G10+COUNTIFS('Plan de test'!$C$5:$C$152,"*"&A10&"*",'Plan de test'!$M$5:$M$152,"Non livré")=F10,"Non livrée","En cours")))) | K10: Stock par châssis livré ; les soldes clients et factures ouvertes viennent avec le lot 2
A11: US-007 | B11: EP-01 | C11: La Direction est notifiée de tout changement de droits | D11: Utilisateur, ancien et nouveau droit, auteur | E11: Livré | F11: =COUNTIF('Plan de test'!$C$5:$C$152,"*"&A11&"*") | G11: =COUNTIFS('Plan de test'!$C$5:$C$152,"*"&A11&"*",'Plan de test'!$M$5:$M$152,"Réussi") | H11: =COUNTIFS('Plan de test'!$C$5:$C$152,"*"&A11&"*",'Plan de test'!$M$5:$M$152,"Échec")+COUNTIFS('Plan de test'!$C$5:$C$152,"*"&A11&"*",'Plan de test'!$M$5:$M$152,"Bloqué") | I11: =F11-G11-H11-COUNTIFS('Plan de test'!$C$5:$C$152,"*"&A11&"*",'Plan de test'!$M$5:$M$152,"Non livré") | J11: =IF(F11=0,"Aucun cas",IF(H11>0,"Échec",IF(G11=F11,"Validée",IF(G11+COUNTIFS('Plan de test'!$C$5:$C$152,"*"&A11&"*",'Plan de test'!$M$5:$M$152,"Non livré")=F11,"Non livrée","En cours"))))
A12: US-008 | B12: EP-01 | C12: Recevoir ses tâches en attente en notification | D12: Un clic ouvre l'écran de traitement | E12: Livré | F12: =COUNTIF('Plan de test'!$C$5:$C$152,"*"&A12&"*") | G12: =COUNTIFS('Plan de test'!$C$5:$C$152,"*"&A12&"*",'Plan de test'!$M$5:$M$152,"Réussi") | H12: =COUNTIFS('Plan de test'!$C$5:$C$152,"*"&A12&"*",'Plan de test'!$M$5:$M$152,"Échec")+COUNTIFS('Plan de test'!$C$5:$C$152,"*"&A12&"*",'Plan de test'!$M$5:$M$152,"Bloqué") | I12: =F12-G12-H12-COUNTIFS('Plan de test'!$C$5:$C$152,"*"&A12&"*",'Plan de test'!$M$5:$M$152,"Non livré") | J12: =IF(F12=0,"Aucun cas",IF(H12>0,"Échec",IF(G12=F12,"Validée",IF(G12+COUNTIFS('Plan de test'!$C$5:$C$152,"*"&A12&"*",'Plan de test'!$M$5:$M$152,"Non livré")=F12,"Non livrée","En cours"))))
A13: US-010 | B13: EP-02 | C13: Créer un modèle avec ses prix | D13: Code article unique ; minimum ≤ vente | E13: Livré | F13: =COUNTIF('Plan de test'!$C$5:$C$152,"*"&A13&"*") | G13: =COUNTIFS('Plan de test'!$C$5:$C$152,"*"&A13&"*",'Plan de test'!$M$5:$M$152,"Réussi") | H13: =COUNTIFS('Plan de test'!$C$5:$C$152,"*"&A13&"*",'Plan de test'!$M$5:$M$152,"Échec")+COUNTIFS('Plan de test'!$C$5:$C$152,"*"&A13&"*",'Plan de test'!$M$5:$M$152,"Bloqué") | I13: =F13-G13-H13-COUNTIFS('Plan de test'!$C$5:$C$152,"*"&A13&"*",'Plan de test'!$M$5:$M$152,"Non livré") | J13: =IF(F13=0,"Aucun cas",IF(H13>0,"Échec",IF(G13=F13,"Validée",IF(G13+COUNTIFS('Plan de test'!$C$5:$C$152,"*"&A13&"*",'Plan de test'!$M$5:$M$152,"Non livré")=F13,"Non livrée","En cours"))))
A14: US-011 | B14: EP-02 | C14: Changer un prix avec une date d'effet | D14: Commandes validées gardent leur prix ; historique visible | E14: Partiel | F14: =COUNTIF('Plan de test'!$C$5:$C$152,"*"&A14&"*") | G14: =COUNTIFS('Plan de test'!$C$5:$C$152,"*"&A14&"*",'Plan de test'!$M$5:$M$152,"Réussi") | H14: =COUNTIFS('Plan de test'!$C$5:$C$152,"*"&A14&"*",'Plan de test'!$M$5:$M$152,"Échec")+COUNTIFS('Plan de test'!$C$5:$C$152,"*"&A14&"*",'Plan de test'!$M$5:$M$152,"Bloqué") | I14: =F14-G14-H14-COUNTIFS('Plan de test'!$C$5:$C$152,"*"&A14&"*",'Plan de test'!$M$5:$M$152,"Non livré") | J14: =IF(F14=0,"Aucun cas",IF(H14>0,"Échec",IF(G14=F14,"Validée",IF(G14+COUNTIFS('Plan de test'!$C$5:$C$152,"*"&A14&"*",'Plan de test'!$M$5:$M$152,"Non livré")=F14,"Non livrée","En cours")))) | K14: Historique livré ; commandes clients au lot 2
A15: US-012 | B15: EP-02 | C15: Fiche châssis : toute son histoire | D15: Statut, emplacement, événements datés avec auteur ; coût masqué sans permission | E15: Livré | F15: =COUNTIF('Plan de test'!$C$5:$C$152,"*"&A15&"*") | G15: =COUNTIFS('Plan de test'!$C$5:$C$152,"*"&A15&"*",'Plan de test'!$M$5:$M$152,"Réussi") | H15: =COUNTIFS('Plan de test'!$C$5:$C$152,"*"&A15&"*",'Plan de test'!$M$5:$M$152,"Échec")+COUNTIFS('Plan de test'!$C$5:$C$152,"*"&A15&"*",'Plan de test'!$M$5:$M$152,"Bloqué") | I15: =F15-G15-H15-COUNTIFS('Plan de test'!$C$5:$C$152,"*"&A15&"*",'Plan de test'!$M$5:$M$152,"Non livré") | J15: =IF(F15=0,"Aucun cas",IF(H15>0,"Échec",IF(G15=F15,"Validée",IF(G15+COUNTIFS('Plan de test'!$C$5:$C$152,"*"&A15&"*",'Plan de test'!$M$5:$M$152,"Non livré")=F15,"Non livrée","En cours"))))
A16: US-013 | B16: EP-02 | C16: Corriger un numéro de châssis avec validation d'un collègue | D16: Motif ; ancien numéro trouvable ; refus si facturé | E16: Partiel | F16: =COUNTIF('Plan de test'!$C$5:$C$152,"*"&A16&"*") | G16: =COUNTIFS('Plan de test'!$C$5:$C$152,"*"&A16&"*",'Plan de test'!$M$5:$M$152,"Réussi") | H16: =COUNTIFS('Plan de test'!$C$5:$C$152,"*"&A16&"*",'Plan de test'!$M$5:$M$152,"Échec")+COUNTIFS('Plan de test'!$C$5:$C$152,"*"&A16&"*",'Plan de test'!$M$5:$M$152,"Bloqué") | I16: =F16-G16-H16-COUNTIFS('Plan de test'!$C$5:$C$152,"*"&A16&"*",'Plan de test'!$M$5:$M$152,"Non livré") | J16: =IF(F16=0,"Aucun cas",IF(H16>0,"Échec",IF(G16=F16,"Validée",IF(G16+COUNTIFS('Plan de test'!$C$5:$C$152,"*"&A16&"*",'Plan de test'!$M$5:$M$152,"Non livré")=F16,"Non livrée","En cours")))) | K16: Règle « facturé » au lot 2
